Workbook

Sheet 2025-touban-master-sample
B1: @ | J1: グレーのハイライトは当番に該当しない | O1: メモ：保健図書入力可能先
B2: =C2+H2+J2+L2 -> 17 | C2: =COUNTA(C4:C22) -> 10 | D2: 黒字が当番作成委員2が使用している欄。 | H2: =COUNTA(H4:H38)-1 -> 7 | I2: =COUNTA(I4:I38)-1 -> 7 | J2: =COUNTA(J4:J38)-1 -> 0 | K2: =COUNTA(K4:K38)-1 -> 0 | L2: =COUNTA(L4:L38)-1 -> 0 | M2: =COUNTA(M4:M38)-1 -> 0 | T2: ※3-1図書委員は2名です。1人3回当番になるようにアサインお願いします(ブックフェア含まず)。
A3: 事務局登録TEL | B3: No | C3: 学年組 | D3: 氏 名 | E3: 保護者名 | F3: 当番用TEL | G3: 当番用メール | H3: 兄姉２ | I3: 兄姉氏名 | J3: 兄姉３ | K3: 兄姉氏名 | L3: 兄弟 学年 学級 | M3: 兄姉氏名 | N3: 図書 | P3: 保健 | R3: パトロール | T3: 備考 | U3: 編入 | V3: 退学 | W3: 免除対象 | X3: 事務局登録TEL数字のみ | Y3: 旧TEL | Z3: 旧メール | AC3: 変更履歴
B4: 1 | C4: 幼 ゆり | D4: 行列 一蔵 | E4: 親一 | F4: 123-456-1111 | G4: 1111@gmail.com | P4: 45878 | Q4: A | U4: 45759 | W4: 運動会委員
B5: 2 | C5: 幼 ゆり | D5: 行列 二蔵 | E5: 親二 | F5: 123-456-2222 | G5: 2222@gmail.com | H5: 小4－1 | I5: 行列 弟二 | R5: 6/7,9/20 | S5: A,A | U5: 45759 | W5: 安全委員 | X5: =SUBSTITUTE(SUBSTITUTE(SUBSTITUTE(F5,"-",""),"(",""),")","") -> 1234562222
B6: 3 | C6: 幼 ゆり | D6: 行列 三彦 | E6: 親三 | F6: 123-456-3333 | G6: 3333@gmail.com | H6: 小3－1 | I6: 行列 妹三 | N6: 45815 | O6: D | U6: 45759 | X6: =SUBSTITUTE(SUBSTITUTE(SUBSTITUTE(F6,"-",""),"(",""),")","") -> 1234563333
B7: 4 | C7: 幼 ゆり | D7: 行列 四志乃 | E7: 親四 | F7: 123-456-4444 | G7: 4444@gmail.com | H7: 小3－1 | I7: 行列 妹四 | U7: 45759 | W7: 運営関係者 | X7: =SUBSTITUTE(SUBSTITUTE(SUBSTITUTE(F7,"-",""),"(",""),")","") -> 1234564444
B8: 5 | C8: 幼 ゆり | D8: 行列 五和 | E8: 親五 | F8: 123-456-5555 | G8: 5555@gmail.com | P8: 45920 | Q8: A | U8: 45759 | W8: 学級委員 | X8: =SUBSTITUTE(SUBSTITUTE(SUBSTITUTE(F8,"-",""),"(",""),")","") -> 1234565555
B9: 6 | C9: 幼 ゆり | D9: 行列 六郎 | E9: 親六 | F9: 123-456-6666 | G9: 6666@gmail.com | H9: 小2－2 | I9: 行列 弟六 | P9: 45920 | Q9: B | U9: 45759 | W9: 学級委員 | X9: =SUBSTITUTE(SUBSTITUTE(SUBSTITUTE(F9,"-",""),"(",""),")","") -> 1234566666
B10: 7 | C10: 幼 ゆり | D10: 行列 七 | E10: 親七 | F10: 123-456-7777 | G10: 7777@gmail.com | H10: 小3－2 | I10: 行列 弟七 | P10: 45892 | Q10: A | U10: 45759 | X10: =SUBSTITUTE(SUBSTITUTE(SUBSTITUTE(F10,"-",""),"(",""),")","") -> 1234567777
B11: 8 | C11: 幼 ゆり | D11: 行列 八蟹 | E11: 親八 | F11: 123-456-8888 | G11: 8888@gmail.com | H11: 小2－2 | I11: 行列 弟八 | P11: 45815 | Q11: B | U11: 45759 | X11: =SUBSTITUTE(SUBSTITUTE(SUBSTITUTE(F11,"-",""),"(",""),")","") -> 1234568888
B12: 9 | C12: 幼 ゆり | D12: 行列 九里 | E12: 親九 | F12: 123-456-9999 | G12: 9999@gmail.com | P12: 45871 | Q12: A | U12: 45759 | X12: =SUBSTITUTE(SUBSTITUTE(SUBSTITUTE(F12,"-",""),"(",""),")","") -> 1234569999
B13: 10 | C13: 幼 ゆり | D13: 行列 十助 | E13: 親十 | F13: 123-456-0000 | G13: 0000@gmail.com | H13: 小4－1 | I13: 行列 妹十 | P13: 45871 | Q13: B | U13: 45759 | X13: =SUBSTITUTE(SUBSTITUTE(SUBSTITUTE(F13,"-",""),"(",""),")","") -> 1234560000
D14: 1 | E14: 2 | F14: 3 | G14: 4 | H14: 5 | I14: 6 | J14: 7 | K14: 8 | L14: 9 | M14: 10 | N14: 11 | O14: 12 | P14: 13 | Q14: 14 | R14: 15 | S14: 16 | T14: 17 | U14: 18 | V14: 19 | W14: 20 | X14: 21 | Y14: 22 | Z14: 23

Sheet 2023当番マスター(旧)
F1: Telとメール赤字は当番用のみの番号。事務局の登録番号とは異なる | K1: グレーのハイライトは当番に該当しない | O1: メモ：保健図書入力可能先
T2: ※3-1図書委員は2名です。1人3回当番になるようにアサインお願いします(ブックフェア含まず)。
A3: 事務局登録TEL | B3: No | C3: 学年組 | D3: 氏 名 | E3: 保護者名 | F3: 当番用TEL | G3: 当番用メール | H3: 兄姉２ | I3: 兄姉氏名 | J3: 兄姉３ | K3: 兄姉氏名 | L3: 兄姉４ | M3: 兄姉氏名 | N3: 図書 | P3: 保健 | R3: パトロール | T3: 備考 | U3: 編入 | V3: 退学 | W3: 免除対象 | X3: 選出 | Y3: 事務局登録TEL | Z3: クラス登録メール | AA3: 3/2データ参照 | AB3: 3/2データ参照 | AC3: 3/2データ参照 | AD3: 3/2データ参照 | AE3: 3/2データ参照 | AF3: 3/2データ参照 | AG3: 3/2データ参照 | AH3: 事務局登録TEL数字のみ | AI3: 免除者Lookup
A4: (478)228-9270 | B4: 1 | C4: 幼 ゆり | D4: 高瀬 瑛太 | E4: 良平 | F4: (478)228-9270 | G4: rtakase0921@gmail.com;mtaka523.ktm@gmail.com | H4: 小3－1 | I4: 高瀬 翔太 | N4: 45045 | O4: A | W4: 図書委員 | Y4: (478)228-9270 | Z4: mtaka523.ktm@gmail.com | AA4: =VLOOKUP(Y4,20230302Data!A:K,2,FALSE()) -> 幼 ゆり | AB4: =VLOOKUP(Y4,20230302Data!A:K,3,FALSE()) -> 高瀬 瑛太 | AC4: =VLOOKUP(Y4,20230302Data!A:K,4,FALSE()) -> 良平 | AD4: =VLOOKUP(Y4,20230302Data!A:K,6,FALSE()) -> 小3－1 | AE4: =VLOOKUP(Y4,20230302Data!A:K,7,FALSE()) -> 高瀬 翔太 | AF4: =VLOOKUP(Y4,20230302Data!A:K,8,FALSE()) -> 0 | AG4: =VLOOKUP(Y4,20230302Data!A:K,9,FALSE()) -> 0 | AH4: =SUBSTITUTE(SUBSTITUTE(SUBSTITUTE(Y4,"-",""),"(",""),")","") -> 4782289270 | AI4: =IFERROR(VLOOKUP(AH4,#REF!,3,FALSE()),"")
A5: (424)201-9432 | B5: 2 | C5: 幼 ゆり | D5: 清水 悠羽 | E5: 純雄 | F5: (424)201-9432 | G5: yoshikofuse@yahoo.co.jp;sumio79@yahoo.co.jp | R5: 45038 | S5: B | V5: 45094 | Y5: (424)201-9432 | Z5: yoshikofuse@yahoo.co.jp | AA5: =VLOOKUP(Y5,20230302Data!A:K,2,FALSE()) -> 幼 ゆり | AB5: =VLOOKUP(Y5,20230302Data!A:K,3,FALSE()) -> 清水 悠羽 | AC5: =VLOOKUP(Y5,20230302Data!A:K,4,FALSE()) -> 純雄 | AD5: =VLOOKUP(Y5,20230302Data!A:K,6,FALSE()) -> 0 | AE5: =VLOOKUP(Y5,20230302Data!A:K,7,FALSE()) -> 0 | AF5: =VLOOKUP(Y5,20230302Data!A:K,8,FALSE()) -> 0 | AG5: =VLOOKUP(Y5,20230302Data!A:K,9,FALSE()) -> 0 | AH5: =SUBSTITUTE(SUBSTITUTE(SUBSTITUTE(Y5,"-",""),"(",""),")","") -> 4242019432 | AI5: =IFERROR(VLOOKUP(AH5,#REF!,3,FALSE()),"")
A6: (678)308-1514 | B6: 3 | C6: 幼 ゆり | D6: 津田 悠真 | E6: 真矢 | F6: (678)308-1514 | G6: aiko.tda@gmail.com | H6: 小2－2 | I6: 津田 真咲 | W6: 運動会委員 | Y6: (678)308-1514 | Z6: aiko.tda@gmail.com | AA6: =VLOOKUP(Y6,20230302Data!A:K,2,FALSE()) -> 幼 ゆり | AB6: =VLOOKUP(Y6,20230302Data!A:K,3,FALSE()) -> 津田 悠真 | AC6: =VLOOKUP(Y6,20230302Data!A:K,4,FALSE()) -> 真矢 | AD6: =VLOOKUP(Y6,20230302Data!A:K,6,FALSE()) -> 小2－2 | AE6: =VLOOKUP(Y6,20230302Data!A:K,7,FALSE()) -> 津田 真咲 | AF6: =VLOOKUP(Y6,20230302Data!A:K,8,FALSE()) -> 0 | AG6: =VLOOKUP(Y6,20230302Data!A:K,9,FALSE()) -> 0 | AH6: =SUBSTITUTE(SUBSTITUTE(SUBSTITUTE(Y6,"-",""),"(",""),")","") -> 6783081514 | AI6: =IFERROR(VLOOKUP(AH6,#REF!,3,FALSE()),"")
A7: (678)727-6990 | B7: 4 | C7: 幼 ゆり | D7: 田代 匠 | E7: 悠一郎 | F7: (678)727-6990 | G7: minorinoaki33@outlook.jp | H7: 小4－1 | I7: 田代 実 | N7: 45066 | O7: D | Y7: (678)727-6990 | Z7: minorinoaki33@outlook.jp | AA7: =VLOOKUP(Y7,20230302Data!A:K,2,FALSE()) -> 幼 ゆり | AB7: =VLOOKUP(Y7,20230302Data!A:K,3,FALSE()) -> 田代 匠 | AC7: =VLOOKUP(Y7,20230302Data!A:K,4,FALSE()) -> 悠一郎 | AD7: =VLOOKUP(Y7,20230302Data!A:K,6,FALSE()) -> 小4－1 | AE7: =VLOOKUP(Y7,20230302Data!A:K,7,FALSE()) -> 田代 実 | AF7: =VLOOKUP(Y7,20230302Data!A:K,8,FALSE()) -> 0 | AG7: =VLOOKUP(Y7,20230302Data!A:K,9,FALSE()) -> 0 | AH7: =SUBSTITUTE(SUBSTITUTE(SUBSTITUTE(Y7,"-",""),"(",""),")","") -> 6787276990 | AI7: =IFERROR(VLOOKUP(AH7,#REF!,3,FALSE()),"")
A8: (646)345-9335 | B8: 5 | C8: 幼 ゆり | D8: 船戸 建志 | E8: 洸佑 | F8: (646)345-9335 | G8: kosuke.and.saori@gmail.com | R8: 45052 | S8: C | Y8: (646)345-9335 | Z8: kosuke.and.saori@gmail.com | AA8: =VLOOKUP(Y8,20230302Data!A:K,2,FALSE()) -> 幼 ゆり | AB8: =VLOOKUP(Y8,20230302Data!A:K,3,FALSE()) -> 船戸 建志 | AC8: =VLOOKUP(Y8,20230302Data!A:K,4,FALSE()) -> 洸佑 | AD8: =VLOOKUP(Y8,20230302Data!A:K,6,FALSE()) -> 0 | AE8: =VLOOKUP(Y8,20230302Data!A:K,7,FALSE()) -> 0 | AF8: =VLOOKUP(Y8,20230302Data!A:K,8,FALSE()) -> 0 | AG8: =VLOOKUP(Y8,20230302Data!A:K,9,FALSE()) -> 0 | AH8: =SUBSTITUTE(SUBSTITUTE(SUBSTITUTE(Y8,"-",""),"(",""),")","") -> 6463459335 | AI8: =IFERROR(VLOOKUP(AH8,#REF!,3,FALSE()),"")
A9: (240)602-4877 | B9: 6 | C9: 幼 ゆり | D9: 渡部 浩市 | E9: 浩 | F9: (240)602-4877 | G9: kimikoaratani@yahoo.com | H9: 小2－1 | I9: 渡部 公太 | W9: 学級委員 | X9: 幼 ゆり | Y9: (240)602-4877 | Z9: kimikoaratani@yahoo.com;hiroshi20723@yahoo.co.jp | AA9: =VLOOKUP(Y9,20230302Data!A:K,2,FALSE()) -> 幼 ゆり | AB9: =VLOOKUP(Y9,20230302Data!A:K,3,FALSE()) -> 渡部 浩市 | AC9: =VLOOKUP(Y9,20230302Data!A:K,4,FALSE()) -> 浩 | AD9: =VLOOKUP(Y9,20230302Data!A:K,6,FALSE()) -> 小2－1 | AE9: =VLOOKUP(Y9,20230302Data!A:K,7,FALSE()) -> 渡部 公太 | AF9: =VLOOKUP(Y9,20230302Data!A:K,8,FALSE()) -> 0 | AG9: =VLOOKUP(Y9,20230302Data!A:K,9,FALSE()) -> 0 | AH9: =SUBSTITUTE(SUBSTITUTE(SUBSTITUTE(Y9,"-",""),"(",""),")","") -> 2406024877 | AI9: =IFERROR(VLOOKUP(AH9,#REF!,3,FALSE()),"")
A10: (470)488-9747 | B10: 7 | C10: 幼 ゆり | D10: 冨永 奈央 | E10: 浩平 | F10: (470)488-9747 | G10: tominagakohei7@gmail.com | H10: 小2－1 | I10: 冨永 純平 | W10: 運営関係者 | X10: 幼、小２ | Y10: (470)488-9747 | Z10: tominagakohei7@gmail.com | AA10: =VLOOKUP(Y10,20230302Data!A:K,2,FALSE()) -> 幼 ゆり | AB10: =VLOOKUP(Y10,20230302Data!A:K,3,FALSE()) -> 冨永 奈央 | AC10: =VLOOKUP(Y10,20230302Data!A:K,4,FALSE()) -> 浩平 | AD10: =VLOOKUP(Y10,20230302Data!A:K,6,FALSE()) -> 小2－1 | AE10: =VLOOKUP(Y10,20230302Data!A:K,7,FALSE()) -> 冨永 純平 | AF10: =VLOOKUP(Y10,20230302Data!A:K,8,FALSE()) -> 0 | AG10: =VLOOKUP(Y10,20230302Data!A:K,9,FALSE()) -> 0 | AH10: =SUBSTITUTE(SUBSTITUTE(SUBSTITUTE(Y10,"-",""),"(",""),")","") -> 4704889747 | AI10: =IFERROR(VLOOKUP(AH10,#REF!,3,FALSE()),"")
A11: (770)235-8197 | B11: 8 | C11: 幼 ゆり | D11: 岩戸 友莉菜 | E11: 友宏 | F11: (770)235-8197 | G11: chika46yuri123tomo927@gmail.com | W11: 運動会委員 | Y11: (770)235-8197 | Z11: chika46yuri123tomo927@gmail.com | AA11: =VLOOKUP(Y11,20230302Data!A:K,2,FALSE()) -> 幼 ゆり | AB11: =VLOOKUP(Y11,20230302Data!A:K,3,FALSE()) -> 岩戸 友莉菜 | AC11: =VLOOKUP(Y11,20230302Data!A:K,4,FALSE()) -> 友宏 | AD11: =VLOOKUP(Y11,20230302Data!A:K,6,FALSE()) -> 0 | AE11: =VLOOKUP(Y11,20230302Data!A:K,7,FALSE()) -> 0 | AF11: =VLOOKUP(Y11,20230302Data!A:K,8,FALSE()) -> 0 | AG11: =VLOOKUP(Y11,20230302Data!A:K,9,FALSE()) -> 0 | AH11: =SUBSTITUTE(SUBSTITUTE(SUBSTITUTE(Y11,"-",""),"(",""),")","") -> 7702358197 | AI11: =IFERROR(VLOOKUP(AH11,#REF!,3,FALSE()),"")
A12: (678)575-8187 | B12: 9 | C12: 幼 ゆり | D12: 江川 椎香 | E12: 良 | F12: (470)461-7192 | G12: makeorbreak.0728@gmail.com | H12: 小2－3 | I12: 江川 紗彩 | W12: 行事委員 | X12: 幼 ゆり | Y12: (678)575-8187 | Z12: makeorbreak.0728@gmail.com | AA12: =VLOOKUP(Y12,20230302Data!A:K,2,FALSE()) -> 幼 ゆり | AB12: =VLOOKUP(Y12,20230302Data!A:K,3,FALSE()) -> 江川 椎香 | AC12: =VLOOKUP(Y12,20230302Data!A:K,4,FALSE()) -> 良 | AD12: =VLOOKUP(Y12,20230302Data!A:K,6,FALSE()) -> 小2－3 | AE12: =VLOOKUP(Y12,20230302Data!A:K,7,FALSE()) -> 江川 紗彩 | AF12: =VLOOKUP(Y12,20230302Data!A:K,8,FALSE()) -> 0 | AG12: =VLOOKUP(Y12,20230302Data!A:K,9,FALSE()) -> 0 | AH12: =SUBSTITUTE(SUBSTITUTE(SUBSTITUTE(Y12,"-",""),"(",""),")","") -> 6785758187 | AI12: =IFERROR(VLOOKUP(AH12,#REF!,3,FALSE()),"")
A13: (470)576-0018 | B13: 10 | C13: 幼 ゆり | D13: 佐藤 友紀美 | E13: 清隆 | F13: (470)576-0018 | G13: satofami.kyhsy@gmail.com | H13: 小2－1 | I13: 佐藤 清花 | J13: 小4－1 | K13: 佐藤 ほのか | W13: 運営関係者 | X13: 幼,小２，小４ | Y13: (470)576-0018 | Z13: satofami.kyhsy@gmail.com | AA13: =VLOOKUP(Y13,20230302Data!A:K,2,FALSE()) -> 幼 ゆり | AB13: =VLOOKUP(Y13,20230302Data!A:K,3,FALSE()) -> 佐藤 友紀美 | AC13: =VLOOKUP(Y13,20230302Data!A:K,4,FALSE()) -> 清隆 | AD13: =VLOOKUP(Y13,20230302Data!A:K,6,FALSE()) -> 小2－1 | AE13: =VLOOKUP(Y13,20230302Data!A:K,7,FALSE()) -> 佐藤 清花 | AF13: =VLOOKUP(Y13,20230302Data!A:K,8,FALSE()) -> 小4－1 | AG13: =VLOOKUP(Y13,20230302Data!A:K,9,FALSE()) -> 佐藤 ほのか | AH13: =SUBSTITUTE(SUBSTITUTE(SUBSTITUTE(Y13,"-",""),"(",""),")","") -> 4705760018 | AI13: =IFERROR(VLOOKUP(AH13,#REF!,3,FALSE()),"")
A14: (678)464-7084 | B14: 11 | C14: 幼 ゆり | D14: 川部 和紗 | E14: 亘 | F14: (678)464-7084 | G14: kinokonoyama62.hk@gmail.com;wataru.kawabe@us.panasonic.com | H14: 小2－1 | I14: 川部 楓太 | N14: 45038 | O14: D | Y14: (678)464-7084 | Z14: wataru.kawabe@us.panasonic.com | AA14: =VLOOKUP(Y14,20230302Data!A:K,2,FALSE()) -> 幼 ゆり | AB14: =VLOOKUP(Y14,20230302Data!A:K,3,FALSE()) -> 川部 和紗 | AC14: =VLOOKUP(Y14,20230302Data!A:K,4,FALSE()) -> 亘 | AD14: =VLOOKUP(Y14,20230302Data!A:K,6,FALSE()) -> 小2－1 | AE14: =VLOOKUP(Y14,20230302Data!A:K,7,FALSE()) -> 川部 楓太 | AF14: =VLOOKUP(Y14,20230302Data!A:K,8,FALSE()) -> 0 | AG14: =VLOOKUP(Y14,20230302Data!A:K,9,FALSE()) -> 0 | AH14: =SUBSTITUTE(SUBSTITUTE(SUBSTITUTE(Y14,"-",""),"(",""),")","") -> 6784647084 | AI14: =IFERROR(VLOOKUP(AH14,#REF!,3,FALSE()),"")
A15: (678)576-4453 | B15: 12 | C15: 幼 ゆり | D15: 西島 江真 | E15: 裕介 | F15: (678)576-4453 | G15: n.yusuke0923@gmail.com | H15: 小2－1 | I15: 西島 浩貴 | N15: 45052 | O15: C | W15: 図書委員 | X15: 小２－１ | Y15: (678)576-4453 | Z15: n.yusuke0923@gmail.com;kanayamamoto78@gmail.com | AA15: =VLOOKUP(Y15,20230302Data!A:K,2,FALSE()) -> 幼 ゆり | AB15: =VLOOKUP(Y15,20230302Data!A:K,3,FALSE()) -> 西島 江真 | AC15: =VLOOKUP(Y15,20230302Data!A:K,4,FALSE()) -> 裕介 | AD15: =VLOOKUP(Y15,20230302Data!A:K,6,FALSE()) -> 小2－1 | AE15: =VLOOKUP(Y15,20230302Data!A:K,7,FALSE()) -> 西島 浩貴 | AF15: =VLOOKUP(Y15,20230302Data!A:K,8,FALSE()) -> 0 | AG15: =VLOOKUP(Y15,20230302Data!A:K,9,FALSE()) -> 0 | AH15: =SUBSTITUTE(SUBSTITUTE(SUBSTITUTE(Y15,"-",""),"(",""),")","") -> 6785764453 | AI15: =IFERROR(VLOOKUP(AH15,#REF!,3,FALSE()),"")
A16: (678)677-1769 | B16: 13 | C16: 幼 ゆり | D16: ホーイ 碧蘭 | E16: テリー | F16: (678)677-1769 | G16: lumisa22@gmail.com | W16: 50周年行事委員 | Y16: (678)677-1769 | Z16: lumisa22@gmail.com;ksakakura07@gmail.com | AA16: =VLOOKUP(Y16,20230302Data!A:K,2,FALSE()) -> 幼 ゆり | AB16: =VLOOKUP(Y16,20230302Data!A:K,3,FALSE()) -> ホーイ 碧蘭 | AC16: =VLOOKUP(Y16,20230302Data!A:K,4,FALSE()) -> テリー | AD16: =VLOOKUP(Y16,20230302Data!A:K,6,FALSE()) -> 0 | AE16: =VLOOKUP(Y16,20230302Data!A:K,7,FALSE()) -> 0 | AF16: =VLOOKUP(Y16,20230302Data!A:K,8,FALSE()) -> 0 | AG16: =VLOOKUP(Y16,20230302Data!A:K,9,FALSE()) -> 0 | AH16: =SUBSTITUTE(SUBSTITUTE(SUBSTITUTE(Y16,"-",""),"(",""),")","") -> 6786771769 | AI16: =IFERROR(VLOOKUP(AH16,#REF!,3,FALSE()),"")
A17: (770)235-1224 | B17: 14 | C17: 幼 ゆり | D17: 六反 梛月 | E17: 耕太 | F17: (770)235-1224 | G17: tsugumirokutan@gmail.com | H17: 小3－2 | I17: 六反 千遥 | J17: 小5－1 | K17: 六反 智葵 | W17: 運動会委員 | Y17: (770)235-1224 | Z17: tsugumirokutan@gmail.com | AA17: =VLOOKUP(Y17,20230302Data!A:K,2,FALSE()) -> 幼 ゆり | AB17: =VLOOKUP(Y17,20230302Data!A:K,3,FALSE()) -> 六反 梛月 | AC17: =VLOOKUP(Y17,20230302Data!A:K,4,FALSE()) -> 耕太 | AD17: =VLOOKUP(Y17,20230302Data!A:K,6,FALSE()) -> 小3－2 | AE17: =VLOOKUP(Y17,20230302Data!A:K,7,FALSE()) -> 六反 千遥 | AF17: =VLOOKUP(Y17,20230302Data!A:K,8,FALSE()) -> 小5－1 | AG17: =VLOOKUP(Y17,20230302Data!A:K,9,FALSE()) -> 六反 智葵 | AH17: =SUBSTITUTE(SUBSTITUTE(SUBSTITUTE(Y17,"-",""),"(",""),")","") -> 7702351224 | AI17: =IFERROR(VLOOKUP(AH17,#REF!,3,FALSE()),"")
A18: (470)269-6658 | B18: 15 | C18: 幼 ゆり | D18: 伊藤 みずき | E18: 敦史 | F18: (470)269-6658 | G18: sunshine.mariko@gmail.com | H18: 小2－2 | I18: 伊藤 さくら | J18: 小2－3 | K18: 伊藤 あずさ | W18: 学級委員 | Y18: (470)269-6658 | Z18: sunshine.mariko@gmail.com;atsushi1214meister@gmail.com | AA18: =VLOOKUP(Y18,20230302Data!A:K,2,FALSE()) -> 幼 ゆり | AB18: =VLOOKUP(Y18,20230302Data!A:K,3,FALSE()) -> 伊藤 みずき | AC18: =VLOOKUP(Y18,20230302Data!A:K,4,FALSE()) -> 敦史 | AD18: =VLOOKUP(Y18,20230302Data!A:K,6,FALSE()) -> 小2－2 | AE18: =VLOOKUP(Y18,20230302Data!A:K,7,FALSE()) -> 伊藤 さくら | AF18: =VLOOKUP(Y18,20230302Data!A:K,8,FALSE()) -> 小2－3 | AG18: =VLOOKUP(Y18,20230302Data!A:K,9,FALSE()) -> 伊藤 あずさ | AH18: =SUBSTITUTE(SUBSTITUTE(SUBSTITUTE(Y18,"-",""),"(",""),")","") -> 4702696658 | AI18: =IFERROR(VLOOKUP(AH18,#REF!,3,FALSE()),"")
A19: (404)771-9497 | B19: 16 | C19: 幼 ゆり | D19: 木下 さら | E19: 郁子 | F19: (404)771-9497 | G19: sunnyikopp@gmail.com | W19: 50周年行事委員 | Y19: (404)771-9497 | Z19: sunnyikopp@gmail.com | AA19: =VLOOKUP(Y19,20230302Data!A:K,2,FALSE()) -> 幼 ゆり | AB19: =VLOOKUP(Y19,20230302Data!A:K,3,FALSE()) -> 木下 さら | AC19: =VLOOKUP(Y19,20230302Data!A:K,4,FALSE()) -> 博登 | AD19: =VLOOKUP(Y19,20230302Data!A:K,6,FALSE()) -> 0 | AE19: =VLOOKUP(Y19,20230302Data!A:K,7,FALSE()) -> 0 | AF19: =VLOOKUP(Y19,20230302Data!A:K,8,FALSE()) -> 0 | AG19: =VLOOKUP(Y19,20230302Data!A:K,9,FALSE()) -> 0 | AH19: =SUBSTITUTE(SUBSTITUTE(SUBSTITUTE(Y19,"-",""),"(",""),")","") -> 4047719497 | AI19: =IFERROR(VLOOKUP(AH19,#REF!,3,FALSE()),"")
A20: (470)796-0060 | B20: 17 | C20: 幼 ゆり | D20: 塚越 豊 | E20: 肇 | F20: (470)796-0060 | G20: ham_tsuka@yahoo.co.jp | U20: 44674 | Y20: (470)796-0060 | Z20: ham_tsuka@yahoo.co.jp | AA20: =VLOOKUP(Y20,20230302Data!A:K,2,FALSE()) -> 幼 ゆり | AB20: =VLOOKUP(Y20,20230302Data!A:K,3,FALSE()) -> 塚越 豊 | AC20: =VLOOKUP(Y20,20230302Data!A:K,4,FALSE()) -> 肇 | AD20: =VLOOKUP(Y20,20230302Data!A:K,6,FALSE()) -> 0 | AE20: =VLOOKUP(Y20,20230302Data!A:K,7,FALSE()) -> 0 | AF20: =VLOOKUP(Y20,20230302Data!A:K,8,FALSE()) -> 0 | AG20: =VLOOKUP(Y20,20230302Data!A:K,9,FALSE()) -> 0 | AH20: =SUBSTITUTE(SUBSTITUTE(SUBSTITUTE(Y20,"-",""),"(",""),")","") -> 4707960060 | AI20: =IFERROR(VLOOKUP(AH20,#REF!,3,FALSE()),"")
A21: (513)857-8977 | B21: 18 | C21: 幼 ゆり | D21: 齋藤 翔 | E21: 正昭 | F21: (513)857-8977 | G21: mayuyutsu8007@icloud.com | V21: 45073 | Y21: (513)857-8977 | Z21: mayuyutsu8007@icloud.com | AA21: =VLOOKUP(Y21,20230302Data!A:K,2,FALSE()) -> 幼 ゆり | AB21: =VLOOKUP(Y21,20230302Data!A:K,3,FALSE()) -> 齋藤 翔 | AC21: =VLOOKUP(Y21,20230302Data!A:K,4,FALSE()) -> 正昭 | AD21: =VLOOKUP(Y21,20230302Data!A:K,6,FALSE()) -> 0 | AE21: =VLOOKUP(Y21,20230302Data!A:K,7,FALSE()) -> 0 | AF21: =VLOOKUP(Y21,20230302Data!A:K,8,FALSE()) -> 0 | AG21: =VLOOKUP(Y21,20230302Data!A:K,9,FALSE()) -> 0 | AH21: =SUBSTITUTE(SUBSTITUTE(SUBSTITUTE(Y21,"-",""),"(",""),")","") -> 5138578977 | AI21: =IFERROR(VLOOKUP(AH21,#REF!,3,FALSE()),"")
A22: (706)766-2725 | B22: 19 | C22: 幼 もも | D22: 山﨑 圭悟 | E22: 智昭 | F22: (706)766-2725 | G22: zaki.tomo.yuka@gmail.com | Y22: (706)766-2725 | Z22: zaki.tomo.yuka@gmail.com | AA22: =VLOOKUP(Y22,20230302Data!A:K,2,FALSE()) -> 幼 もも | AB22: =VLOOKUP(Y22,20230302Data!A:K,3,FALSE()) -> 山﨑 圭悟 | AC22: =VLOOKUP(Y22,20230302Data!A:K,4,FALSE()) -> 智昭 | AD22: =VLOOKUP(Y22,20230302Data!A:K,6,FALSE()) -> 0 | AE22: =VLOOKUP(Y22,20230302Data!A:K,7,FALSE()) -> 0 | AF22: =VLOOKUP(Y22,20230302Data!A:K,8,FALSE()) -> 0 | AG22: =VLOOKUP(Y22,20230302Data!A:K,9,FALSE()) -> 0 | AH22: =SUBSTITUTE(SUBSTITUTE(SUBSTITUTE(Y22,"-",""),"(",""),")","") -> 7067662725 | AI22: =IFERROR(VLOOKUP(AH22,#REF!,3,FALSE()),"")
A23: (678)237-1373 | B23: 20 | C23: 幼 もも | D23: 山口 将太 | E23: 圭介 | F23: (678)237-1373 | G23: ekus313@yahoo.co.jp;punipuniaiko@gmail.com | H23: 中2－1 | I23: 山口 美奈子 | N23: 45066 | O23: A | W23: 図書委員 | X23: 中２－１ | Y23: (678)237-1373 | Z23: punipuniaiko@gmail.com | AA23: =VLOOKUP(Y23,20230302Data!A:K,2,FALSE()) -> 幼 もも | AB23: =VLOOKUP(Y23,20230302Data!A:K,3,FALSE()) -> 山口 将太 | AC23: =VLOOKUP(Y23,20230302Data!A:K,4,FALSE()) -> 圭介 | AD23: =VLOOKUP(Y23,20230302Data!A:K,6,FALSE()) -> 中2－1 | AE23: =VLOOKUP(Y23,20230302Data!A:K,7,FALSE()) -> 山口 美奈子 | AF23: =VLOOKUP(Y23,20230302Data!A:K,8,FALSE()) -> 0 | AG23: =VLOOKUP(Y23,20230302Data!A:K,9,FALSE()) -> 0 | AH23: =SUBSTITUTE(SUBSTITUTE(SUBSTITUTE(Y23,"-",""),"(",""),")","") -> 6782371373 | AI23: =IFERROR(VLOOKUP(AH23,#REF!,3,FALSE()),"")
A24: (678)371-0304 | B24: 21 | C24: 幼 もも | D24: 池永 海生 | E24: ジャック | F24: (678)371-0304 | G24: nikenaga@yahoo.com | H24: 小2－1 | I24: 池永 眞弥 | N24: 45073 | O24: C | W24: 図書委員 | X24: 幼 もも | Y24: (678)371-0304 | Z24: nikenaga@yahoo.com | AA24: =VLOOKUP(Y24,20230302Data!A:K,2,FALSE()) -> 幼 もも | AB24: =VLOOKUP(Y24,20230302Data!A:K,3,FALSE()) -> 池永 海生 | AC24: =VLOOKUP(Y24,20230302Data!A:K,4,FALSE()) -> ジャック | AD24: =VLOOKUP(Y24,20230302Data!A:K,6,FALSE()) -> 小2－1 | AE24: =VLOOKUP(Y24,20230302Data!A:K,7,FALSE()) -> 池永 眞弥 | AF24: =VLOOKUP(Y24,20230302Data!A:K,8,FALSE()) -> 0 | AG24: =VLOOKUP(Y24,20230302Data!A:K,9,FALSE()) -> 0 | AH24: =SUBSTITUTE(SUBSTITUTE(SUBSTITUTE(Y24,"-",""),"(",""),")","") -> 6783710304 | AI24: =IFERROR(VLOOKUP(AH24,#REF!,3,FALSE()),"")
A25: (678)296-7245 | B25: 22 | C25: 幼 もも | D25: 小田 哲哉 | E25: 康史 | F25: (678)296-7245 | G25: tomo1129tb3@gmail.com | H25: 小2－2 | I25: 小田 彰士 | W25: 50周年行事委員 | Y25: (678)296-7245 | Z25: tomo1129tb3@gmail.com | AA25: =VLOOKUP(Y25,20230302Data!A:K,2,FALSE()) -> 幼 もも | AB25: =VLOOKUP(Y25,20230302Data!A:K,3,FALSE()) -> 小田 哲哉 | AC25: =VLOOKUP(Y25,20230302Data!A:K,4,FALSE()) -> 康史 | AD25: =VLOOKUP(Y25,20230302Data!A:K,6,FALSE()) -> 小2－2 | AE25: =VLOOKUP(Y25,20230302Data!A:K,7,FALSE()) -> 小田 彰士 | AF25: =VLOOKUP(Y25,20230302Data!A:K,8,FALSE()) -> 0 | AG25: =VLOOKUP(Y25,20230302Data!A:K,9,FALSE()) -> 0 | AH25: =SUBSTITUTE(SUBSTITUTE(SUBSTITUTE(Y25,"-",""),"(",""),")","") -> 6782967245 | AI25: =IFERROR(VLOOKUP(AH25,#REF!,3,FALSE()),"")
A26: (704)654-0730 | B26: 23 | C26: 幼 もも | D26: 鈴木 康平 | E26: 秀典 | F26: (704)654-0730 | G26: hsuzuki@live.com;suzuki.mio@outlook.com | P26: 45052 | Q26: B | W26: 行事委員 | X26: 幼 もも | Y26: (704)654-0730 | Z26: suzuki.mio@outlook.com;Hsuzuki@live.com | AA26: =VLOOKUP(Y26,20230302Data!A:K,2,FALSE()) -> 幼 もも | AB26: =VLOOKUP(Y26,20230302Data!A:K,3,FALSE()) -> 鈴木 康平 | AC26: =VLOOKUP(Y26,20230302Data!A:K,4,FALSE()) -> 秀典 | AD26: =VLOOKUP(Y26,20230302Data!A:K,6,FALSE()) -> 0 | AE26: =VLOOKUP(Y26,20230302Data!A:K,7,FALSE()) -> 0 | AF26: =VLOOKUP(Y26,20230302Data!A:K,8,FALSE()) -> 0 | AG26: =VLOOKUP(Y26,20230302Data!A:K,9,FALSE()) -> 0 | AH26: =SUBSTITUTE(SUBSTITUTE(SUBSTITUTE(Y26,"-",""),"(",""),")","") -> 7046540730 | AI26: =IFERROR(VLOOKUP(AH26,#REF!,3,FALSE()),"")
A27: (770)580-9260 | B27: 24 | C27: 幼 もも | D27: 宮嶋 悠一郎 | E27: 望 | F27: (770)580-9260 | G27: gongdaowang@hotmail.co.jp;spring_mh@hotmail.com | H27: 小3－1 | I27: 宮嶋 希子 | W27: 安全対策委員 | X27: 幼 ゆり | Y27: (770)580-9260 | Z27: spring_mh@hotmail.com | AA27: =VLOOKUP(Y27,20230302Data!A:K,2,FALSE()) -> 幼 もも | AB27: =VLOOKUP(Y27,20230302Data!A:K,3,FALSE()) -> 宮嶋 悠一郎 | AC27: =VLOOKUP(Y27,20230302Data!A:K,4,FALSE()) -> 望 | AD27: =VLOOKUP(Y27,20230302Data!A:K,6,FALSE()) -> 小3－1 | AE27: =VLOOKUP(Y27,20230302Data!A:K,7,FALSE()) -> 宮嶋 希子 | AF27: =VLOOKUP(Y27,20230302Data!A:K,8,FALSE()) -> 0 | AG27: =VLOOKUP(Y27,20230302Data!A:K,9,FALSE()) -> 0 | AH27: =SUBSTITUTE(SUBSTITUTE(SUBSTITUTE(Y27,"-",""),"(",""),")","") -> 7705809260 | AI27: =IFERROR(VLOOKUP(AH27,#REF!,3,FALSE()),"")
A28: (352)284-4615 | B28: 25 | C28: 幼 もも | D28: 篠原 佳也 | E28: マイカ | F28: (352)284-4615 | G28: hiroko_shinohara@hotmail.com | W28: 学級委員 | X28: 幼 もも | Y28: (352)284-4615 | Z28: hiroko_shinohara@hotmail.com | AA28: =VLOOKUP(Y28,20230302Data!A:K,2,FALSE()) -> 幼 もも | AB28: =VLOOKUP(Y28,20230302Data!A:K,3,FALSE()) -> 篠原 佳也 | AC28: =VLOOKUP(Y28,20230302Data!A:K,4,FALSE()) -> マイカ | AD28: =VLOOKUP(Y28,20230302Data!A:K,6,FALSE()) -> 0 | AE28: =VLOOKUP(Y28,20230302Data!A:K,7,FALSE()) -> 0 | AF28: =VLOOKUP(Y28,20230302Data!A:K,8,FALSE()) -> 0 | AG28: =VLOOKUP(Y28,20230302Data!A:K,9,FALSE()) -> 0 | AH28: =SUBSTITUTE(SUBSTITUTE(SUBSTITUTE(Y28,"-",""),"(",""),")","") -> 3522844615 | AI28: =IFERROR(VLOOKUP(AH28,#REF!,3,FALSE()),"")
A29: (404)429-0867 | B29: 26 | C29: 幼 もも | D29: 綾部 櫻 | E29: ファリス | F29: (404)429-0867 | G29: naoneko38@msn.com | H29: 小1－3 | I29: 綾部 賢造 | W29: 学級委員 | X29: 小１－３ | Y29: (404)429-0867 | Z29: naoneko38@msn.com | AA29: =VLOOKUP(Y29,20230302Data!A:K,2,FALSE()) -> 幼 もも | AB29: =VLOOKUP(Y29,20230302Data!A:K,3,FALSE()) -> 綾部 櫻 | AC29: =VLOOKUP(Y29,20230302Data!A:K,4,FALSE()) -> ファリス | AD29: =VLOOKUP(Y29,20230302Data!A:K,6,FALSE()) -> 小1－3 | AE29: =VLOOKUP(Y29,20230302Data!A:K,7,FALSE()) -> 綾部 賢造 | AF29: =VLOOKUP(Y29,20230302Data!A:K,8,FALSE()) -> 0 | AG29: =VLOOKUP(Y29,20230302Data!A:K,9,FALSE()) -> 0 | AH29: =SUBSTITUTE(SUBSTITUTE(SUBSTITUTE(Y29,"-",""),"(",""),")","") -> 4044290867 | AI29: =IFERROR(VLOOKUP(AH29,#REF!,3,FALSE()),"")
A30: (678)571-3691 | B30: 27 | C30: 幼 もも | D30: 神村 咲奈 | E30: 洋介 | F30: (678)571-3691 | G30: yukainahitorigoto@gmail.com | W30: 運動会委員 | Y30: (678)571-3691 | Z30: yukainahitorigoto@gmail.com | AA30: =VLOOKUP(Y30,20230302Data!A:K,2,FALSE()) -> 幼 もも | AB30: =VLOOKUP(Y30,20230302Data!A:K,3,FALSE()) -> 神村 咲奈 | AC30: =VLOOKUP(Y30,20230302Data!A:K,4,FALSE()) -> 洋介 | AD30: =VLOOKUP(Y30,20230302Data!A:K,6,FALSE()) -> 0 | AE30: =VLOOKUP(Y30,20230302Data!A:K,7,FALSE()) -> 0 | AF30: =VLOOKUP(Y30,20230302Data!A:K,8,FALSE()) -> 0 | AG30: =VLOOKUP(Y30,20230302Data!A:K,9,FALSE()) -> 0 | AH30: =SUBSTITUTE(SUBSTITUTE(SUBSTITUTE(Y30,"-",""),"(",""),")","") -> 6785713691 | AI30: =IFERROR(VLOOKUP(AH30,#REF!,3,FALSE()),"")
A31: (678)200-3387 | B31: 28 | C31: 幼 もも | D31: 近藤 さくら | E31: 政樹 | F31: (678)200-3387 | G31: qiuzi1012@yahoo.co.jp | H31: 小2－3 | I31: 近藤 巧 | W31: 運営関係者 | Y31: (678)200-3387 | Z31: qiuzi1012@yahoo.co.jp | AA31: =VLOOKUP(Y31,20230302Data!A:K,2,FALSE()) -> 幼 もも | AB31: =VLOOKUP(Y31,20230302Data!A:K,3,FALSE()) -> 近藤 さくら | AC31: =VLOOKUP(Y31,20230302Data!A:K,4,FALSE()) -> 政樹 | AD31: =VLOOKUP(Y31,20230302Data!A:K,6,FALSE()) -> 小2－3 | AE31: =VLOOKUP(Y31,20230302Data!A:K,7,FALSE()) -> 近藤 巧 | AF31: =VLOOKUP(Y31,20230302Data!A:K,8,FALSE()) -> 0 | AG31: =VLOOKUP(Y31,20230302Data!A:K,9,FALSE()) -> 0 | AH31: =SUBSTITUTE(SUBSTITUTE(SUBSTITUTE(Y31,"-",""),"(",""),")","") -> 6782003387 | AI31: =IFERROR(VLOOKUP(AH31,#REF!,3,FALSE()),"")
A32: (404)202-3437 | B32: 29 | C32: 幼 もも | D32: 富澤 結衣 | E32: 明 | F32: (404)202-3437 | G32: ekawa411@gmail.com | W32: 学級委員 | Y32: (404)202-3437 | Z32: ekawa411@gmail.com | AA32: =VLOOKUP(Y32,20230302Data!A:K,2,FALSE()) -> 幼 もも | AB32: =VLOOKUP(Y32,20230302Data!A:K,3,FALSE()) -> 富澤 結衣 | AC32: =VLOOKUP(Y32,20230302Data!A:K,4,FALSE()) -> 明 | AD32: =VLOOKUP(Y32,20230302Data!A:K,6,FALSE()) -> 0 | AE32: =VLOOKUP(Y32,20230302Data!A:K,7,FALSE()) -> 0 | AF32: =VLOOKUP(Y32,20230302Data!A:K,8,FALSE()) -> 0 | AG32: =VLOOKUP(Y32,20230302Data!A:K,9,FALSE()) -> 0 | AH32: =SUBSTITUTE(SUBSTITUTE(SUBSTITUTE(Y32,"-",""),"(",""),")","") -> 4042023437 | AI32: =IFERROR(VLOOKUP(AH32,#REF!,3,FALSE()),"")
A33: (678)897-3721 | B33: 30 | C33: 幼 もも | D33: 林 美和 | E33: 悠 | F33: (678)897-3721 | G33: yukkokko.526@gmail.com;yu.hayashi@kubota.com | H33: 小2－3 | I33: 林 美桜 | W33: 学級委員 | Y33: (678)897-3721 | Z33: yu.hayashi@kubota.com;yukkokko.526@gmail.com | AA33: =VLOOKUP(Y33,20230302Data!A:K,2,FALSE()) -> 幼 もも | AB33: =VLOOKUP(Y33,20230302Data!A:K,3,FALSE()) -> 林 美和 | AC33: =VLOOKUP(Y33,20230302Data!A:K,4,FALSE()) -> 悠 | AD33: =VLOOKUP(Y33,20230302Data!A:K,6,FALSE()) -> 小2－3 | AE33: =VLOOKUP(Y33,20230302Data!A:K,7,FALSE()) -> 林 美桜 | AF33: =VLOOKUP(Y33,20230302Data!A:K,8,FALSE()) -> 0 | AG33: =VLOOKUP(Y33,20230302Data!A:K,9,FALSE()) -> 0 | AH33: =SUBSTITUTE(SUBSTITUTE(SUBSTITUTE(Y33,"-",""),"(",""),")","") -> 6788973721 | AI33: =IFERROR(VLOOKUP(AH33,#REF!,3,FALSE()),"")
A34: (678)315-9092 | B34: 31 | C34: 幼 もも | D34: 益田 華 | E34: 拓朗 | F34: (404)447-4884 | G34: takuro.masuda@gmail.com | Y34: (678)315-9092 | Z34: takuro.masuda@gmail.com | AA34: =VLOOKUP(Y34,20230302Data!A:K,2,FALSE()) -> 幼 もも | AB34: =VLOOKUP(Y34,20230302Data!A:K,3,FALSE()) -> 益田 華 | AC34: =VLOOKUP(Y34,20230302Data!A:K,4,FALSE()) -> 拓朗 | AD34: =VLOOKUP(Y34,20230302Data!A:K,6,FALSE()) -> 0 | AE34: =VLOOKUP(Y34,20230302Data!A:K,7,FALSE()) -> 0 | AF34: =VLOOKUP(Y34,20230302Data!A:K,8,FALSE()) -> 0 | AG34: =VLOOKUP(Y34,20230302Data!A:K,9,FALSE()) -> 0 | AH34: =SUBSTITUTE(SUBSTITUTE(SUBSTITUTE(Y34,"-",""),"(",""),")","") -> 6783159092 | AI34: =IFERROR(VLOOKUP(AH34,#REF!,3,FALSE()),"")
A35: (706)934-3352 | B35: 32 | C35: 幼 もも | D35: 森本 七瀬 | E35: 祐輔 | F35: (706)934-3352 | G35: yuko_in_nor@yahoo.co.jp | Y35: (706)934-3352 | Z35: yuko_in_nor@yahoo.co.jp | AA35: =VLOOKUP(Y35,20230302Data!A:K,2,FALSE()) -> 幼 もも | AB35: =VLOOKUP(Y35,20230302Data!A:K,3,FALSE()) -> 森本 七瀬 | AC35: =VLOOKUP(Y35,20230302Data!A:K,4,FALSE()) -> 祐輔 | AD35: =VLOOKUP(Y35,20230302Data!A:K,6,FALSE()) -> 0 | AE35: =VLOOKUP(Y35,20230302Data!A:K,7,FALSE()) -> 0 | AF35: =VLOOKUP(Y35,20230302Data!A:K,8,FALSE()) -> 0 | AG35: =VLOOKUP(Y35,20230302Data!A:K,9,FALSE()) -> 0 | AH35: =SUBSTITUTE(SUBSTITUTE(SUBSTITUTE(Y35,"-",""),"(",""),")","") -> 7069343352 | AI35: =IFERROR(VLOOKUP(AH35,#REF!,3,FALSE()),"")
A36: (470)519-5525 | B36: 34 | C36: 幼 もも | D36: 山根 悠希 | E36: 聡 | F36: (470)519-5525 | G36: knjys@yahoo.co.jp | H36: 小2－1 | I36: 山根 綾乃 | J36: 小5－2 | K36: 山根 陸 | N36: 45045 | O36: B | U36: 44674 | W36: 図書委員 | Y36: (470)519-5525 | Z36: knjys@yahoo.co.jp | AA36: =VLOOKUP(Y36,20230302Data!A:K,2,FALSE()) -> 幼 もも | AB36: =VLOOKUP(Y36,20230302Data!A:K,3,FALSE()) -> 山根 悠希 | AC36: =VLOOKUP(Y36,20230302Data!A:K,4,FALSE()) -> 聡 | AD36: =VLOOKUP(Y36,20230302Data!A:K,6,FALSE()) -> 小2－1 | AE36: =VLOOKUP(Y36,20230302Data!A:K,7,FALSE()) -> 山根 綾乃 | AF36: =VLOOKUP(Y36,20230302Data!A:K,8,FALSE()) -> 小5－2 | AG36: =VLOOKUP(Y36,20230302Data!A:K,9,FALSE()) -> 山根 陸 | AH36: =SUBSTITUTE(SUBSTITUTE(SUBSTITUTE(Y36,"-",""),"(",""),")","") -> 4705195525 | AI36: =IFERROR(VLOOKUP(AH36,#REF!,3,FALSE()),"")
A37: (770)314-7618 | B37: 35 | C37: 幼 もも | D37: 磯部 美桜 | E37: 大介 | F37: (770)314-7618 | G37: daisuke_isobe@na.honda.com | H37: 小3－2 | I37: 磯部 侑理 | U37: 44779 | W37: 運動会委員 | Y37: (770)314-7618 | Z37: daisuke_isobe@na.honda.com | AA37: =VLOOKUP(Y37,20230302Data!A:K,2,FALSE()) -> 幼 もも | AB37: =VLOOKUP(Y37,20230302Data!A:K,3,FALSE()) -> 磯部 美桜 | AC37: =VLOOKUP(Y37,20230302Data!A:K,4,FALSE()) -> 大介 | AD37: =VLOOKUP(Y37,20230302Data!A:K,6,FALSE()) -> 小3－2 | AE37: =VLOOKUP(Y37,20230302Data!A:K,7,FALSE()) -> 磯部 侑理 | AF37: =VLOOKUP(Y37,20230302Data!A:K,8,FALSE()) -> 0 | AG37: =VLOOKUP(Y37,20230302Data!A:K,9,FALSE()) -> 0 | AH37: =SUBSTITUTE(SUBSTITUTE(SUBSTITUTE(Y37,"-",""),"(",""),")","") -> 7703147618 | AI37: =IFERROR(VLOOKUP(AH37,#REF!,3,FALSE()),"")
A38: (310)809-5341 | B38: 36 | C38: 幼 もも | D38: 西 竜輝 | E38: 佑樹 | F38: (310)809-5341 | G38: kaoru.mtt@gmail.com | H38: 小4－1 | I38: 西 朝輝 | J38: 小5－1 | K38: 西 美咲 | W38: 行事委員 | X38: 小４－１ | Y38: (310)809-5341 | Z38: Kaoru.mtt@gmail.com | AA38: =VLOOKUP(Y38,20230302Data!A:K,2,FALSE()) -> 幼 もも | AB38: =VLOOKUP(Y38,20230302Data!A:K,3,FALSE()) -> 西 竜輝 | AC38: =VLOOKUP(Y38,20230302Data!A:K,4,FALSE()) -> 佑樹 | AD38: =VLOOKUP(Y38,20230302Data!A:K,6,FALSE()) -> 小4－1 | AE38: =VLOOKUP(Y38,20230302Data!A:K,7,FALSE()) -> 西 朝輝 | AF38: =VLOOKUP(Y38,20230302Data!A:K,8,FALSE()) -> 小5－1 | AG38: =VLOOKUP(Y38,20230302Data!A:K,9,FALSE()) -> 西 美咲 | AH38: =SUBSTITUTE(SUBSTITUTE(SUBSTITUTE(Y38,"-",""),"(",""),")","") -> 3108095341 | AI38: =IFERROR(VLOOKUP(AH38,#REF!,3,FALSE()),"")
A39: (770)309-3296 | B39: 37 | C39: 小1－1 | D39: 上原 圭翔 | E39: 悠 | F39: (770)309-3296 | G39: yuehara710@gmail.com;suehara314@gmail.com | W39: 運動会委員 | X39: 小１－１ | Y39: (770)309-3296 | Z39: suehara314@gmail.com | AA39: =VLOOKUP(Y39,20230302Data!A:K,2,FALSE()) -> 小1－1 | AB39: =VLOOKUP(Y39,20230302Data!A:K,3,FALSE()) -> 上原 圭翔 | AC39: =VLOOKUP(Y39,20230302Data!A:K,4,FALSE()) -> 悠 | AD39: =VLOOKUP(Y39,20230302Data!A:K,6,FALSE()) -> 0 | AE39: =VLOOKUP(Y39,20230302Data!A:K,7,FALSE()) -> 0 | AF39: =VLOOKUP(Y39,20230302Data!A:K,8,FALSE()) -> 0 | AG39: =VLOOKUP(Y39,20230302Data!A:K,9,FALSE()) -> 0 | AH39: =SUBSTITUTE(SUBSTITUTE(SUBSTITUTE(Y39,"-",""),"(",""),")","") -> 7703093296 | AI39: =IFERROR(VLOOKUP(AH39,#REF!,3,FALSE()),"")
A40: (770)885-5784 | B40: 38 | C40: 小1－1 | D40: 鈴木 賢斗 | E40: ジェームス | F40: (770)885-5784 | G40: takayo.witmondt@gmail.com | Y40: (770)885-5784 | Z40: takayo.witmondt@gmail.com | AA40: =VLOOKUP(Y40,20230302Data!A:K,2,FALSE()) -> 小1－1 | AB40: =VLOOKUP(Y40,20230302Data!A:K,3,FALSE()) -> 鈴木 賢斗 | AC40: =VLOOKUP(Y40,20230302Data!A:K,4,FALSE()) -> ジェームス | AD40: =VLOOKUP(Y40,20230302Data!A:K,6,FALSE()) -> 0 | AE40: =VLOOKUP(Y40,20230302Data!A:K,7,FALSE()) -> 0 | AF40: =VLOOKUP(Y40,20230302Data!A:K,8,FALSE()) -> 0 | AG40: =VLOOKUP(Y40,20230302Data!A:K,9,FALSE()) -> 0 | AH40: =SUBSTITUTE(SUBSTITUTE(SUBSTITUTE(Y40,"-",""),"(",""),")","") -> 7708855784 | AI40: =IFERROR(VLOOKUP(AH40,#REF!,3,FALSE()),"")
...

Sheet 20230302Data
A1: TEL番号 | B1: 学年組 | C1: 氏 名 | D1: 保護者名 | E1: TEL番号 | F1: 兄姉２ | G1: 兄姉氏名 | H1: 兄姉３ | I1: 兄姉氏名 | J1: 兄姉４ | K1: 兄姉氏名 | L1: vlookup with Master2023 | M1: vlookup with Master2022
A2: (678)727-6990 | B2: 幼 ゆり | C2: 田代 匠 | D2: 悠一郎 | E2: (678)727-6990 | F2: 小4－1 | G2: 田代 実 | L2: =VLOOKUP(A2,'2023当番マスター(旧)'!A:D,4,FALSE()) -> 田代 匠 | M2: =VLOOKUP(A2,2022当番マスター!A:E,4,FALSE()) -> 田代 匠
A3: (478)228-9270 | B3: 幼 ゆり | C3: 高瀬 瑛太 | D3: 良平 | E3: (478)228-9270 | F3: 小3－1 | G3: 高瀬 翔太 | L3: =VLOOKUP(A3,'2023当番マスター(旧)'!A:D,4,FALSE()) -> 高瀬 瑛太 | M3: =VLOOKUP(A3,2022当番マスター!A:E,4,FALSE()) -> 高瀬 瑛太
A4: (646)345-9335 | B4: 幼 ゆり | C4: 船戸 建志 | D4: 洸佑 | E4: (646)345-9335 | L4: =VLOOKUP(A4,'2023当番マスター(旧)'!A:D,4,FALSE()) -> 船戸 建志 | M4: =VLOOKUP(A4,2022当番マスター!A:E,4,FALSE()) -> 船戸 建志
A5: (678)308-1514 | B5: 幼 ゆり | C5: 津田 悠真 | D5: 真矢 | E5: (678)308-1514 | F5: 小2－2 | G5: 津田 真咲 | L5: =VLOOKUP(A5,'2023当番マスター(旧)'!A:D,4,FALSE()) -> 津田 悠真 | M5: =VLOOKUP(A5,2022当番マスター!A:E,4,FALSE()) -> 津田 悠真
A6: (240)602-4877 | B6: 幼 ゆり | C6: 渡部 浩市 | D6: 浩 | E6: (240)602-4877 | F6: 小2－1 | G6: 渡部 公太 | L6: =VLOOKUP(A6,'2023当番マスター(旧)'!A:D,4,FALSE()) -> 渡部 浩市 | M6: =VLOOKUP(A6,2022当番マスター!A:E,4,FALSE()) -> 渡部 浩市
A7: (470)796-0060 | B7: 幼 ゆり | C7: 塚越 豊 | D7: 肇 | E7: (470)796-0060 | L7: =VLOOKUP(A7,'2023当番マスター(旧)'!A:D,4,FALSE()) -> 塚越 豊 | M7: =VLOOKUP(A7,2022当番マスター!A:E,4,FALSE()) -> 塚越 豊
A8: (513)857-8977 | B8: 幼 ゆり | C8: 齋藤 翔 | D8: 正昭 | E8: (513)857-8977 | L8: =VLOOKUP(A8,'2023当番マスター(旧)'!A:D,4,FALSE()) -> 齋藤 翔 | M8: =VLOOKUP(A8,2022当番マスター!A:E,4,FALSE()) -> 齋藤 翔
A9: (424)201-9432 | B9: 幼 ゆり | C9: 清水 悠羽 | D9: 純雄 | E9: (424)201-9432 | L9: =VLOOKUP(A9,'2023当番マスター(旧)'!A:D,4,FALSE()) -> 清水 悠羽 | M9: =VLOOKUP(A9,2022当番マスター!A:E,4,FALSE()) -> 清水 悠羽
A10: (678)576-4453 | B10: 幼 ゆり | C10: 西島 江真 | D10: 裕介 | E10: (678)576-4453 | F10: 小2－1 | G10: 西島 浩貴 | L10: =VLOOKUP(A10,'2023当番マスター(旧)'!A:D,4,FALSE()) -> 西島 江真 | M10: =VLOOKUP(A10,2022当番マスター!A:E,4,FALSE()) -> 西島 江真
A11: (770)235-8197 | B11: 幼 ゆり | C11: 岩戸 友莉菜 | D11: 友宏 | E11: (770)235-8197 | L11: =VLOOKUP(A11,'2023当番マスター(旧)'!A:D,4,FALSE()) -> 岩戸 友莉菜 | M11: =VLOOKUP(A11,2022当番マスター!A:E,4,FALSE()) -> 岩戸 友莉菜
A12: (678)575-8187 | B12: 幼 ゆり | C12: 江川 椎香 | D12: 良 | E12: (678)575-8187 | F12: 小2－3 | G12: 江川 紗彩 | L12: =VLOOKUP(A12,'2023当番マスター(旧)'!A:D,4,FALSE()) -> 江川 椎香 | M12: =VLOOKUP(A12,2022当番マスター!A:E,4,FALSE()) -> #N/A
A13: (404)771-9497 | B13: 幼 ゆり | C13: 木下 さら | D13: 博登 | E13: (404)771-9497 | L13: =VLOOKUP(A13,'2023当番マスター(旧)'!A:D,4,FALSE()) -> 木下 さら | M13: =VLOOKUP(A13,2022当番マスター!A:E,4,FALSE()) -> 木下 さら
A14: (470)488-9747 | B14: 幼 ゆり | C14: 冨永 奈央 | D14: 浩平 | E14: (470)488-9747 | F14: 小2－1 | G14: 冨永 純平 | L14: =VLOOKUP(A14,'2023当番マスター(旧)'!A:D,4,FALSE()) -> 冨永 奈央 | M14: =VLOOKUP(A14,2022当番マスター!A:E,4,FALSE()) -> 冨永 奈央
A15: (678)677-1769 | B15: 幼 ゆり | C15: ホーイ 碧蘭 | D15: テリー | E15: (678)677-1769 | L15: =VLOOKUP(A15,'2023当番マスター(旧)'!A:D,4,FALSE()) -> ホーイ 碧蘭 | M15: =VLOOKUP(A15,2022当番マスター!A:E,4,FALSE()) -> ホーイ 碧蘭
A16: (770)235-1224 | B16: 幼 ゆり | C16: 六反 梛月 | D16: 耕太 | E16: (770)235-1224 | F16: 小3－2 | G16: 六反 千遥 | H16: 小5－1 | I16: 六反 智葵 | L16: =VLOOKUP(A16,'2023当番マスター(旧)'!A:D,4,FALSE()) -> 六反 梛月 | M16: =VLOOKUP(A16,2022当番マスター!A:E,4,FALSE()) -> 六反 梛月
A17: (470)269-6658 | B17: 幼 ゆり | C17: 伊藤 みずき | D17: 敦史 | E17: (470)269-6658 | F17: 小2－2 | G17: 伊藤 さくら | H17: 小2－3 | I17: 伊藤 あずさ | L17: =VLOOKUP(A17,'2023当番マスター(旧)'!A:D,4,FALSE()) -> 伊藤 みずき | M17: =VLOOKUP(A17,2022当番マスター!A:E,4,FALSE()) -> 伊藤 みずき
A18: (678)464-7084 | B18: 幼 ゆり | C18: 川部 和紗 | D18: 亘 | E18: (678)464-7084 | F18: 小2－1 | G18: 川部 楓太 | L18: =VLOOKUP(A18,'2023当番マスター(旧)'!A:D,4,FALSE()) -> 川部 和紗 | M18: =VLOOKUP(A18,2022当番マスター!A:E,4,FALSE()) -> 川部 和紗
A19: (470)576-0018 | B19: 幼 ゆり | C19: 佐藤 友紀美 | D19: 清隆 | E19: (470)576-0018 | F19: 小2－1 | G19: 佐藤 清花 | H19: 小4－1 | I19: 佐藤 ほのか | L19: =VLOOKUP(A19,'2023当番マスター(旧)'!A:D,4,FALSE()) -> 佐藤 友紀美 | M19: =VLOOKUP(A19,2022当番マスター!A:E,4,FALSE()) -> 佐藤 友紀美
A20: (706)766-2725 | B20: 幼 もも | C20: 山﨑 圭悟 | D20: 智昭 | E20: (706)766-2725 | L20: =VLOOKUP(A20,'2023当番マスター(旧)'!A:D,4,FALSE()) -> 山﨑 圭悟 | M20: =VLOOKUP(A20,2022当番マスター!A:E,4,FALSE()) -> 山﨑 圭悟
A21: (770)580-9260 | B21: 幼 もも | C21: 宮嶋 悠一郎 | D21: 望 | E21: (770)580-9260 | F21: 小3－1 | G21: 宮嶋 希子 | L21: =VLOOKUP(A21,'2023当番マスター(旧)'!A:D,4,FALSE()) -> 宮嶋 悠一郎 | M21: =VLOOKUP(A21,2022当番マスター!A:E,4,FALSE()) -> 宮嶋 悠一郎
A22: (678)237-1373 | B22: 幼 もも | C22: 山口 将太 | D22: 圭介 | E22: (678)237-1373 | F22: 中2－1 | G22: 山口 美奈子 | L22: =VLOOKUP(A22,'2023当番マスター(旧)'!A:D,4,FALSE()) -> 山口 将太 | M22: =VLOOKUP(A22,2022当番マスター!A:E,4,FALSE()) -> 山口 将太
A23: (678)371-0304 | B23: 幼 もも | C23: 池永 海生 | D23: ジャック | E23: (678)371-0304 | F23: 小2－1 | G23: 池永 眞弥 | L23: =VLOOKUP(A23,'2023当番マスター(旧)'!A:D,4,FALSE()) -> 池永 海生 | M23: =VLOOKUP(A23,2022当番マスター!A:E,4,FALSE()) -> 池永 海生
A24: (678)296-7245 | B24: 幼 もも | C24: 小田 哲哉 | D24: 康史 | E24: (678)296-7245 | F24: 小2－2 | G24: 小田 彰士 | L24: =VLOOKUP(A24,'2023当番マスター(旧)'!A:D,4,FALSE()) -> 小田 哲哉 | M24: =VLOOKUP(A24,2022当番マスター!A:E,4,FALSE()) -> 小田 哲哉
A25: (706)980-3859 | B25: 幼 もも | C25: 作元 瑛太 | D25: 正和 | E25: (706)980-3859 | F25: 小4－1 | G25: 作元 要太 | L25: =VLOOKUP(A25,'2023当番マスター(旧)'!A:D,4,FALSE()) -> #N/A | M25: =VLOOKUP(A25,2022当番マスター!A:E,4,FALSE()) -> 作元 瑛太
A26: (310)809-5341 | B26: 幼 もも | C26: 西 竜輝 | D26: 佑樹 | E26: (310)809-5341 | F26: 小4－1 | G26: 西 朝輝 | H26: 小5－1 | I26: 西 美咲 | L26: =VLOOKUP(A26,'2023当番マスター(旧)'!A:D,4,FALSE()) -> 西 竜輝 | M26: =VLOOKUP(A26,2022当番マスター!A:E,4,FALSE()) -> 西 竜輝
A27: (704)654-0730 | B27: 幼 もも | C27: 鈴木 康平 | D27: 秀典 | E27: (704)654-0730 | L27: =VLOOKUP(A27,'2023当番マスター(旧)'!A:D,4,FALSE()) -> 鈴木 康平 | M27: =VLOOKUP(A27,2022当番マスター!A:E,4,FALSE()) -> 鈴木 康平
A28: (470)519-5525 | B28: 幼 もも | C28: 山根 悠希 | D28: 聡 | E28: (470)519-5525 | F28: 小2－1 | G28: 山根 綾乃 | H28: 小5－2 | I28: 山根 陸 | L28: =VLOOKUP(A28,'2023当番マスター(旧)'!A:D,4,FALSE()) -> 山根 悠希 | M28: =VLOOKUP(A28,2022当番マスター!A:E,4,FALSE()) -> 山根 悠希
A29: (352)284-4615 | B29: 幼 もも | C29: 篠原 佳也 | D29: マイカ | E29: (352)284-4615 | L29: =VLOOKUP(A29,'2023当番マスター(旧)'!A:D,4,FALSE()) -> 篠原 佳也 | M29: =VLOOKUP(A29,2022当番マスター!A:E,4,FALSE()) -> 篠原 佳也
A30: (678)200-3387 | B30: 幼 もも | C30: 近藤 さくら | D30: 政樹 | E30: (678)200-3387 | F30: 小2－3 | G30: 近藤 巧 | L30: =VLOOKUP(A30,'2023当番マスター(旧)'!A:D,4,FALSE()) -> 近藤 さくら | M30: =VLOOKUP(A30,2022当番マスター!A:E,4,FALSE()) -> 近藤 さくら
A31: (404)202-3437 | B31: 幼 もも | C31: 富澤 結衣 | D31: 明 | E31: (404)202-3437 | L31: =VLOOKUP(A31,'2023当番マスター(旧)'!A:D,4,FALSE()) -> 富澤 結衣 | M31: =VLOOKUP(A31,2022当番マスター!A:E,4,FALSE()) -> 富澤 結衣
A32: (678)897-3721 | B32: 幼 もも | C32: 林 美和 | D32: 悠 | E32: (678)897-3721 | F32: 小2－3 | G32: 林 美桜 | L32: =VLOOKUP(A32,'2023当番マスター(旧)'!A:D,4,FALSE()) -> 林 美和 | M32: =VLOOKUP(A32,2022当番マスター!A:E,4,FALSE()) -> 林 美和
A33: (678)315-9092 | B33: 幼 もも | C33: 益田 華 | D33: 拓朗 | E33: (678)315-9092 | L33: =VLOOKUP(A33,'2023当番マスター(旧)'!A:D,4,FALSE()) -> 益田 華 | M33: =VLOOKUP(A33,2022当番マスター!A:E,4,FALSE()) -> 益田 華
A34: (706)934-3352 | B34: 幼 もも | C34: 森本 七瀬 | D34: 祐輔 | E34: (706)934-3352 | L34: =VLOOKUP(A34,'2023当番マスター(旧)'!A:D,4,FALSE()) -> 森本 七瀬 | M34: =VLOOKUP(A34,2022当番マスター!A:E,4,FALSE()) -> 森本 七瀬
A35: (404)429-0867 | B35: 幼 もも | C35: 綾部 櫻 | D35: ファリス | E35: (404)429-0867 | F35: 小1－3 | G35: 綾部 賢造 | L35: =VLOOKUP(A35,'2023当番マスター(旧)'!A:D,4,FALSE()) -> 綾部 櫻 | M35: =VLOOKUP(A35,2022当番マスター!A:E,4,FALSE()) -> 綾部 櫻
A36: (678)446-9466 | B36: 幼 もも | C36: 木本 咲衣 | D36: 匠 | E36: (678)446-9466 | F36: 小2－3 | G36: 木本 陽真 | L36: =VLOOKUP(A36,'2023当番マスター(旧)'!A:D,4,FALSE()) -> #N/A | M36: =VLOOKUP(A36,2022当番マスター!A:E,4,FALSE()) -> 木本 咲衣
A37: (770)314-7618 | B37: 幼 もも | C37: 磯部 美桜 | D37: 大介 | E37: (770)314-7618 | F37: 小3－2 | G37: 磯部 侑理 | L37: =VLOOKUP(A37,'2023当番マスター(旧)'!A:D,4,FALSE()) -> 磯部 美桜 | M37: =VLOOKUP(A37,2022当番マスター!A:E,4,FALSE()) -> 磯部 美桜
A38: (678)571-3691 | B38: 幼 もも | C38: 神村 咲奈 | D38: 洋介 | E38: (678)571-3691 | L38: =VLOOKUP(A38,'2023当番マスター(旧)'!A:D,4,FALSE()) -> 神村 咲奈 | M38: =VLOOKUP(A38,2022当番マスター!A:E,4,FALSE()) -> 神村 咲奈
A39: (770)309-3296 | B39: 小1－1 | C39: 上原 圭翔 | D39: 悠 | E39: (770)309-3296 | L39: =VLOOKUP(A39,'2023当番マスター(旧)'!A:D,4,FALSE()) -> 上原 圭翔 | M39: =VLOOKUP(A39,2022当番マスター!A:E,4,FALSE()) -> 上原 圭翔
A40: (770)885-5784 | B40: 小1－1 | C40: 鈴木 賢斗 | D40: ジェームス | E40: (770)885-5784 | L40: =VLOOKUP(A40,'2023当番マスター(旧)'!A:D,4,FALSE()) -> 鈴木 賢斗 | M40: =VLOOKUP(A40,2022当番マスター!A:E,4,FALSE()) -> 鈴木 賢斗
...

Sheet 2022当番マスター
F1: Telとメール赤字は当番用のみの番号。事務局の登録番号とは異なる | K1: グレーのハイライトは当番に該当しない | O1: メモ：保健図書入力可能先
T2: ※3-1図書委員は2名です。1人3回当番になるようにアサインお願いします(ブックフェア含まず)。
A3: 事務局登録TEL | B3: No | C3: 学年組 | D3: 氏 名 | E3: 保護者名 | F3: 当番用TEL | G3: 当番用メール | H3: 兄姉２ | I3: 兄姉氏名 | J3: 兄姉３ | K3: 兄姉氏名 | L3: 兄姉４ | M3: 兄姉氏名 | N3: 図書 | P3: 保健 | R3: パトロール | T3: 備考 | U3: 編入 | V3: 退学 | W3: 免除対象 | X3: 選出 | Y3: 事務局登録TEL | Z3: クラス登録メール
A4: (478)228-9270 | B4: 1 | C4: 幼 ゆり | D4: 高瀬 瑛太 | E4: 良平 | F4: (478)228-9270 | G4: rtakase0921@gmail.com;mtaka523.ktm@gmail.com | H4: 小3－1 | I4: 高瀬 翔太 | N4: 10/8,12/10,2/18 | O4: B,B,A | P4: 44716 | Q4: A | T4: ※退学した畠岡さんと図書委員交代(3-1は図書委員2名)。赤い日付は畠岡さんの残した当番を肩代わり分。 | W4: 図書委員 | X4: 小３−１② | Y4: (478)228-9270 | Z4: mtaka523.ktm@gmail.com
A5: (424)201-9432 | B5: 2 | C5: 幼 ゆり | D5: 清水 悠羽 | E5: 純雄 | F5: (424)201-9432 | G5: yoshikofuse@yahoo.co.jp;sumio79@yahoo.co.jp | P5: 44730 | Q5: A | V5: 45094 | Y5: (424)201-9432 | Z5: yoshikofuse@yahoo.co.jp
A6: (678)308-1514 | B6: 3 | C6: 幼 ゆり | D6: 津田 悠真 | E6: 真矢 | F6: (678)308-1514 | G6: aiko.tda@gmail.com | H6: 小2－2 | I6: 津田 真咲 | P6: 44905 | Q6: B | R6: 44723 | S6: B | Y6: (678)308-1514 | Z6: aiko.tda@gmail.com
A7: (678)727-6990 | B7: 4 | C7: 幼 ゆり | D7: 田代 匠 | E7: 悠一郎 | F7: (678)727-6990 | G7: minorinoaki33@outlook.jp | H7: 小4－1 | I7: 田代 実 | P7: 44674 | Q7: B | R7: 44856 | S7: D | Y7: (678)727-6990 | Z7: minorinoaki33@outlook.jp
A8: (646)345-9335 | B8: 5 | C8: 幼 ゆり | D8: 船戸 建志 | E8: 洸佑 | F8: (646)345-9335 | G8: kosuke.and.saori@gmail.com | P8: 44582 | Q8: B | R8: 44807 | S8: B | Y8: (646)345-9335 | Z8: kosuke.and.saori@gmail.com
A9: (240)602-4877 | B9: 6 | C9: 幼 ゆり | D9: 渡部 浩市 | E9: 浩 | F9: (240)602-4877 | G9: kimikoaratani@yahoo.com | H9: 小2－1 | I9: 渡部 公太 | R9: 44695 | S9: C | W9: 学級委員 | X9: 幼 ゆり | Y9: (240)602-4877 | Z9: kimikoaratani@yahoo.com;hiroshi20723@yahoo.co.jp
A10: (706)386-6298 | B10: 7 | C10: 幼 ゆり | D10: 川島 匠真 | E10: 淳平 | F10: (706)386-6298 | G10: myjptk@yahoo.co.jp | H10: 小2－1 | I10: 川島 一真 | P10: 44863 | Q10: A | R10: 44674 | S10: C | V10: 44912 | Y10: (706)386-6298 | Z10: myjptk@yahoo.co.jp
A11: (470)488-9747 | B11: 8 | C11: 幼 ゆり | D11: 冨永 奈央 | E11: 浩平 | F11: (470)488-9747 | G11: tominagakohei7@gmail.com | H11: 小2－1 | I11: 冨永 純平 | W11: 運営関係者 | X11: 幼、小２ | Y11: (470)488-9747 | Z11: tominagakohei7@gmail.com
A12: (770)235-8197 | B12: 9 | C12: 幼 ゆり | D12: 岩戸 友莉菜 | E12: 友宏 | F12: (770)235-8197 | G12: chika46yuri123tomo927@gmail.com | N12: 44589 | O12: D | R12: 44807 | S12: C | T12: 7/10保護者より電話番号訂正あり➝事務局へ連絡済 | Y12: (770)235-8197 | Z12: chika46yuri123tomo927@gmail.com
A13: (470)461-7192 | B13: 10 | C13: 幼 ゆり | D13: 江川 椎香 | E13: 良 | F13: (470)461-7192 | G13: makeorbreak.0728@gmail.com | H13: 小2－3 | I13: 江川 紗彩 | N13: 5/14＆5/28 | O13: D＆D | R13: ＊ | S13: ＊ | T13: 行事委員にもかかわらず図書当番になったためパトロールは免除か回数少な目で。5/16松本さんと変更。5/28は退学の田中さんの身代わり。 | W13: 行事委員 | X13: 幼 ゆり | Y13: (470)461-7192 | Z13: makeorbreak.0728@gmail.com
A14: (470)576-0018 | B14: 11 | C14: 幼 ゆり | D14: 佐藤 友紀美 | E14: 清隆 | F14: (470)576-0018 | G14: satofami.kyhsy@gmail.com | H14: 小2－1 | I14: 佐藤 清花 | J14: 小4－1 | K14: 佐藤 ほのか | W14: 運営関係者 | X14: 幼,小２，小４ | Y14: (470)576-0018 | Z14: satofami.kyhsy@gmail.com
A15: (678)464-7084 | B15: 12 | C15: 幼 ゆり | D15: 川部 和紗 | E15: 亘 | F15: (678)464-7084 | G15: kinoknoyama62.hk@gmail.com;wataru.kawabe@us.panasonic.com | H15: 小2－1 | I15: 川部 楓太 | N15: 44582 | O15: D | R15: 44793 | S15: C | T15: 9月にアサイン予定だったパトロール当番を、8/20の井口さん(交代者を探さずに退学)と交代して頂きました。 | Y15: (678)464-7084 | Z15: wataru.kawabe@us.panasonic.com
A16: (678)576-4453 | B16: 13 | C16: 幼 ゆり | D16: 西島 江真 | E16: 裕介 | F16: (678)576-4453 | G16: n.yusuke0923@gmail.com | H16: 小2－1 | I16: 西島 浩貴 | R16: 8/6,10/8,1/14 | S16: A | T16: 6月一時帰国の為不在 | W16: 安全対策委員 | X16: 小２－１ | Y16: (678)576-4453 | Z16: n.yusuke0923@gmail.com;kanayamamoto78@gmail.com
A17: (678)677-1769 | B17: 14 | C17: 幼 ゆり | D17: ホーイ 碧蘭 | E17: テリー | F17: (678)677-1769 | G17: lumisa22@gmail.com | N17: 44596 | O17: D | R17: 44821 | S17: B | Y17: (678)677-1769 | Z17: lumisa22@gmail.com;ksakakura07@gmail.com
A18: (470)454-0104 | B18: 15 | C18: 幼 ゆり | D18: 宮園 佳穂 | E18: 海斗 | F18: (470)454-0104 | G18: miho.mmkm16529@gmail.com | H18: 小2－1 | I18: 宮園 洋斗 | N18: 6/4,8/13,9/17,10/29,1/14,3/4 | O18: A,B,A,C,A,C | V18: 44954 | W18: 図書委員 | X18: 幼 ゆり | Y18: (470)454-0104 | Z18: miho.mmkm16529@gmail.com
A19: (770)235-1224 | B19: 16 | C19: 幼 ゆり | D19: 六反 梛月 | E19: 耕太 | F19: (770)235-1224 | G19: tsugumirokutan@gmail.com | H19: 小3－2 | I19: 六反 千遥 | J19: 小5－1 | K19: 六反 智葵 | N19: 1/21,3/11 | O19: C,B | P19: 44702 | Q19: A | R19: 44610 | S19: B | T19: 12/17付で退学した3-2大畑理仁さんの後任で図書委員繰上り | Y19: (770)235-1224 | Z19: tsugumirokutan@gmail.com
A20: (470)269-6658 | B20: 17 | C20: 幼 ゆり | D20: 伊藤 みずき | E20: 敦史 | F20: (470)269-6658 | G20: sunshine.mariko@gmail.com | H20: 小2－2 | I20: 伊藤 さくら | J20: 小2－3 | K20: 伊藤 あずさ | P20: 44863 | Q20: B | R20: 44667 | S20: C | Y20: (470)269-6658 | Z20: sunshine.mariko@gmail.com;atsushi1214meister@gmail.com
A21: (404)771-9497 | B21: 18 | C21: 幼 ゆり | D21: 木下 さら | E21: 博登 | F21: (404)771-9497 | G21: sunnyikopp@gmail.com | N21: 44596 | O21: E | R21: 44821 | S21: C | Y21: (404)771-9497 | Z21: sunnyikopp@gmail.com
A22: (470)796-0060 | B22: 19 | C22: 幼 ゆり | D22: 塚越 豊 | E22: 肇 | F22: (470)796-0060 | G22: ham_tsuka@yahoo.co.jp | P22: 44596 | Q22: A | R22: 44821 | S22: D | U22: 44674 | Y22: (470)796-0060 | Z22: ham_tsuka@yahoo.co.jp
A23: (513)857-8977 | B23: 20 | C23: 幼 ゆり | D23: 齋藤 翔 | E23: 正昭 | F23: (513)857-8977 | G23: mayuyutsu8007@icloud.com | N23: 44589 | O23: E | R23: 44807 | S23: D | V23: 45073 | Y23: (513)857-8977 | Z23: mayuyutsu8007@icloud.com
A24: (706)766-2725 | B24: 21 | C24: 幼 もも | D24: 山﨑 圭悟 | E24: 智昭 | F24: (706)766-2725 | G24: zaki.tomo.yuka@gmail.com | N24: 44716 | O24: D | R24: 44624 | S24: B | Y24: (706)766-2725 | Z24: zaki.tomo.yuka@gmail.com
A25: (678)237-1373 | B25: 22 | C25: 幼 もも | D25: 山口 将太 | E25: 圭介 | F25: (678)237-1373 | G25: ekus313@yahoo.co.jp;punipuniaiko@gmail.com | H25: 中2－1 | I25: 山口 美奈子 | N25: 4/23,5/14,8/27,10/22,1/7,2/25 | O25: C,B,A,B,C,A | W25: 図書委員 | X25: 中２－１ | Y25: (678)237-1373 | Z25: punipuniaiko@gmail.com
A26: (678)371-0304 | B26: 23 | C26: 幼 もも | D26: 池永 海生 | E26: ジャック | F26: (678)371-0304 | G26: nikenaga@yahoo.com | H26: 小2－1 | I26: 池永 眞弥 | N26: 6/4,8/13,10/1,11/12,1/21,3/11 | O26: B,C,A,C,B,A | W26: 図書委員 | X26: 幼 もも | Y26: (678)371-0304 | Z26: nikenaga@yahoo.com
A27: (678)296-7245 | B27: 24 | C27: 幼 もも | D27: 小田 哲哉 | E27: 康史 | F27: (678)296-7245 | G27: tomo1129tb3@gmail.com | H27: 小2－2 | I27: 小田 彰士 | N27: 44877 | O27: D | R27: 44688 | S27: D | Y27: (678)296-7245 | Z27: tomo1129tb3@gmail.com
A28: (706)980-3859 | B28: 25 | C28: 幼 もも | D28: 作元 瑛太 | E28: 正和 | F28: (706)980-3859 | G28: chisato.mail.0714@gmail.com;m.sakumoto17@gmail.com | H28: 小4－1 | I28: 作元 要太 | V28: 45003 | W28: 学級委員 | X28: 小４－１ | Y28: (706)980-3859 | Z28: chisato.mail.0714@gmail.com
A29: (704)654-0730 | B29: 26 | C29: 幼 もも | D29: 鈴木 康平 | E29: 秀典 | F29: (704)654-0730 | G29: hsuzuki@live.com;suzuki.mio@outlook.com | W29: 行事委員 | X29: 幼 もも | Y29: (704)654-0730 | Z29: suzuki.mio@outlook.com;Hsuzuki@live.com
A30: (770)580-9260 | B30: 27 | C30: 幼 もも | D30: 宮嶋 悠一郎 | E30: 望 | F30: (770)580-9260 | G30: gongdaowang@hotmail.co.jp;spring_mh@hotmail.com | H30: 小3－1 | I30: 宮嶋 希子 | R30: 6/4,9/17,12/10,3/11 | S30: A | W30: 安全対策委員 | X30: 幼 ゆり | Y30: (770)580-9260 | Z30: spring_mh@hotmail.com
A31: (352)284-4615 | B31: 28 | C31: 幼 もも | D31: 篠原 佳也 | E31: マイカ | F31: (352)284-4615 | G31: hiroko_shinohara@hotmail.com | W31: 学級委員 | X31: 幼 もも | Y31: (352)284-4615 | Z31: hiroko_shinohara@hotmail.com
A32: (404)429-0867 | B32: 29 | C32: 幼 もも | D32: 綾部 櫻 | E32: ファリス | F32: (404)429-0867 | G32: naoneko38@msn.com | H32: 小1－3 | I32: 綾部 賢造 | W32: 行事委員 | X32: 小１－３ | Y32: (404)429-0867 | Z32: naoneko38@msn.com
A33: (678)571-3691 | B33: 30 | C33: 幼 もも | D33: 神村 咲奈 | E33: 洋介 | F33: (678)571-3691 | G33: yukainahitorigoto@gmail.com | P33: 44800 | Q33: B | T33: happysanaichigo@gmail.comのメルアドは不要 | Y33: (678)571-3691 | Z33: yukainahitorigoto@gmail.com
A34: (678)200-3387 | B34: 31 | C34: 幼 もも | D34: 近藤 さくら | E34: 政樹 | F34: (678)200-3387 | G34: qiuzi1012@yahoo.co.jp | H34: 小2－3 | I34: 近藤 巧 | P34: 44660 | Q34: B | R34: 44870 | S34: E | Y34: (678)200-3387 | Z34: qiuzi1012@yahoo.co.jp
A35: (706)238-3484 | B35: 32 | C35: 幼 もも | D35: 鈴山 たお | E35: 大介 | F35: (706)238-3484 | G35: madokasuzuyama@gmail.com | H35: 小3－2 | I35: 鈴山 大晴 | V35: 44730 | Y35: (706)238-3484 | Z35: madokasuzuyama@gmail.com
A36: (404)202-3437 | B36: 33 | C36: 幼 もも | D36: 富澤 結衣 | E36: 明 | F36: (404)202-3437 | G36: ekawa411@gmail.com | N36: 44912 | O36: D | R36: 44723 | S36: C | Y36: (404)202-3437 | Z36: ekawa411@gmail.com
A37: (678)897-3721 | B37: 34 | C37: 幼 もも | D37: 林 美和 | E37: 悠 | F37: (678)897-3721 | G37: yukkokko.526@gmail.com;yu.hayashi@kubota.com | H37: 小2－3 | I37: 林 美桜 | P37: 44660 | Q37: A | R37: 44870 | S37: F | Y37: (678)897-3721 | Z37: yu.hayashi@kubota.com;yukkokko.526@gmail.com
A38: (678)315-9092 | B38: 35 | C38: 幼 もも | D38: 益田 華 | E38: 拓朗 | F38: (404)447-4884 | G38: takuro.masuda@gmail.com | P38: 44617 | Q38: B | R38: 44856 | S38: B | T38: 当番の際の連絡先変更 | Y38: (678)315-9092 | Z38: takuro.masuda@gmail.com
A39: (706)934-3352 | B39: 36 | C39: 幼 もも | D39: 森本 七瀬 | E39: 祐輔 | F39: (706)934-3352 | G39: yuko_in_nor@yahoo.co.jp | P39: 44617 | Q39: A | R39: 44856 | S39: C | Y39: (706)934-3352 | Z39: yuko_in_nor@yahoo.co.jp
A40: (678)446-9466 | B40: 37 | C40: 幼 もも | D40: 木本 咲衣 | E40: 匠 | F40: (678)446-9466 | G40: mkimoto.1125@gmail.com | H40: 小2－3 | I40: 木本 陽真 | V40: 45003 | W40: 運営関係者 | X40: 幼,小２ | Y40: (678)446-9466 | Z40: mkimoto.1125@gmail.com
...
